<robot name="robobot-v9">
  <!-- <link name="base_link">
  </link> -->

  <link name="body">
    <inertial>
      <origin xyz="0.0 0.0 0.0" rpy="0.0 0.0 0.0"/>
      <mass value="0.0"/>
      <inertia ixx="0.0" ixy="0.0" ixz="0.0" iyy="0.0" iyz="0.0" izz="0.0"/>
    </inertial>
    <visual name="">
      <origin xyz="0.0 0.0 0.0" rpy="0.0 0.0 0.0"/>
      <geometry>
        <mesh filename="package://robobot_v9/mesh/robobot_v9_body.dae" scale="1.0 1.0 1.0"/>
      </geometry>
    </visual>
    <collision>
      <origin xyz="0.0 0.0 0.0" rpy="0.0 0.0 0.0"/>
      <geometry>
        <mesh filename="package://robobot_v9/colliders/robobot_v9_body.stl" scale="1.0 1.0 1.0"/>
      </geometry>
    </collision>
  </link>

  <link name="right_wheel_mount"></link>
  <link name="left_wheel_mount"></link>

  <link name="right_wheel">
    <visual name="">
      <origin xyz="-0.1155 0.1418 -0.075" rpy="0.0 0.0 0.0"/>
      <geometry>
        <mesh filename="package://robobot_v9/mesh/robobot_v9_wheel.dae" scale="1.0 1.0 1.0"/>
      </geometry>
    </visual>
    <collision>
      <origin xyz="-0.1155 0.1418 -0.075" rpy="0.0 0.0 0.0"/>
      <geometry>
        <mesh filename="package://robobot_v9/colliders/robobot_v9_wheel.stl" scale="1.0 1.0 1.0"/>
      </geometry>
    </collision>
  </link>
  <link name="left_wheel">
    <visual name="">
      <origin xyz="0.1155 -0.1418 -0.075" rpy="0.0 0.0 3.14"/>
      <geometry>
        <mesh filename="package://robobot_v9/mesh/robobot_v9_wheel.dae" scale="1.0 1.0 1.0"/>
      </geometry>
    </visual>
    <collision>
      <origin xyz="0.1155 -0.1418 -0.075" rpy="0.0 0.0 3.14"/>
      <geometry>
        <mesh filename="package://robobot_v9/colliders/robobot_v9_wheel.stl" scale="1.0 1.0 1.0"/>
      </geometry>
    </collision>
  </link>
<!-- 
  <joint name="robot" type="floating">
    <parent link="base_link"/>
    <child link="body"/>
  </joint> -->

  <joint name="mount_left" type="fixed">
    <origin xyz="-0.1155 -0.142 0.075" rpy="0.0 0.0 0.0"/>
    <parent link="body"/>
    <child link="left_wheel_mount"/>
  </joint>
  <joint name="mount_right" type="fixed">
    <origin xyz="0.1155 -0.142 0.075" rpy="0.0 0.0 3.14"/>
    <parent link="body"/>
    <child link="right_wheel_mount"/>
  </joint>

  <joint name="right_wheel" type="continuous">
    <parent link="right_wheel_mount"/>
    <child link="right_wheel"/>
    <axis xyz="1.0 0.0 0.0"/>
  </joint>
  <joint name="left_wheel" type="continuous">
    <parent link="left_wheel_mount"/>
    <child link="left_wheel"/>
    <axis xyz="1.0 0.0 0.0"/>
  </joint>

</robot>